<?xml version="1.0" ?>
<!-- This file was generated by robot assembler -->
<robot name="arm_robot3"
       xmlns:xi="http://www.w3.org/2001/XInclude"
       xmlns:gazebo="http://playerstage.sourceforge.net/gazebo/xmlschema/#gz"
       xmlns:model="http://playerstage.sourceforge.net/gazebo/xmlschema/#model"
       xmlns:sensor="http://playerstage.sourceforge.net/gazebo/xmlschema/#sensor"
       xmlns:body="http://playerstage.sourceforge.net/gazebo/xmlschema/#body"
       xmlns:geom="http://playerstage.sourceforge.net/gazebo/xmlschema/#geom"
       xmlns:joint="http://playerstage.sourceforge.net/gazebo/xmlschema/#joint"
       xmlns:interface="http://playerstage.sourceforge.net/gazebo/xmlschema/#interface"
       xmlns:rendering="http://playerstage.sourceforge.net/gazebo/xmlschema/#rendering"
       xmlns:renderable="http://playerstage.sourceforge.net/gazebo/xmlschema/#renderable"
       xmlns:controller="http://playerstage.sourceforge.net/gazebo/xmlschema/#controller"
       xmlns:physics="http://playerstage.sourceforge.net/gazebo/xmlschema/#physics"
       xmlns:xacro="http://www.ros.org/wiki/xacro">
  <xacro:macro name="gazebo_link_reference" params="link_name mu1:=0.9 mu2:=0.9" >
    <gazebo reference="${link_name}">
      <mu1>${mu1}</mu1>
      <mu2>${mu2}</mu2>
    </gazebo>
  </xacro:macro>
  <xacro:macro name="gazebo_transmission" params="joint_name" >
    <transmission name="${joint_name}_trans">
      <type>transmission_interface/SimpleTransmission</type>
      <joint name="${joint_name}">
        <hardwareInterface>hardware_interface/PositionJointInterface</hardwareInterface>
        <!--<hardwareInterface>hardware_interface/VelocityJointInterface</hardwareInterface-->
        <!--hardwareInterface>hardware_interface/EffortJointInterface</hardwareInterface-->
      </joint>
      <actuator name="${joint_name}_motor">
        <hardwareInterface>hardware_interface/PositionJointInterface</hardwareInterface>
        <!--<hardwareInterface>hardware_interface/VelocityJointInterface</hardwareInterface-->
        <!--hardwareInterface>hardware_interface/EffortJointInterface</hardwareInterface-->
        <mechanicalReduction>1</mechanicalReduction>
      </actuator>
    </transmission>
  </xacro:macro>
  <xacro:macro name="no_gazebo_transmission" params="joint_name" >
    <!-- dummy for fixed joint -->
  </xacro:macro>
  <link name="Root" >
    <visual><origin xyz="6.400000000000e-02 6.400000000000e-02 -1.600000000000e-03" rpy="0.000000000000e+00 -0.000000000000e+00 0.000000000000e+00"/><geometry><box size="1.280000000000e-01 1.280000000000e-01 3.200000000000e-03"/></geometry>
</visual>
    <collision><origin xyz="6.400000000000e-02 6.400000000000e-02 -1.600000000000e-03" rpy="0.000000000000e+00 -0.000000000000e+00 0.000000000000e+00"/><geometry><box size="1.280000000000e-01 1.280000000000e-01 3.200000000000e-03"/></geometry>
</collision>
    <inertial>
      <mass value="6.763320000000e-02"/>
      <origin xyz="6.400000000000e-02 6.400000000000e-02 -1.600000000000e-03"/>
      <inertia ixx="9.239950000000e-05" ixy="0.000000000000e+00" ixz="0.000000000000e+00" iyy="9.239950000000e-05" iyz="0.000000000000e+00" izz="1.846840000000e-04"/>
    </inertial>
  </link>
  <link name="plate_4_4_4075_4" >
    <visual><origin xyz="-4.000000000000e-03 4.000000000000e-03 1.600000000000e-03" rpy="0.000000000000e+00 -0.000000000000e+00 0.000000000000e+00"/><geometry><box size="3.200000000000e-02 3.200000000000e-02 3.200000000000e-03"/></geometry>
</visual>
    <collision><origin xyz="-4.000000000000e-03 4.000000000000e-03 1.600000000000e-03" rpy="0.000000000000e+00 -0.000000000000e+00 0.000000000000e+00"/><geometry><box size="3.200000000000e-02 3.200000000000e-02 3.200000000000e-03"/></geometry>
</collision>
    <inertial>
      <mass value="4.227070000000e-03"/>
      <origin xyz="-4.000000000000e-03 4.000000000000e-03 1.600000000000e-03"/>
      <inertia ixx="3.643170000000e-07" ixy="0.000000000000e+00" ixz="0.000000000000e+00" iyy="3.643170000000e-07" iyz="0.000000000000e+00" izz="7.214200000000e-07"/>
    </inertial>
  </link>
  <joint name="plate_4_4_4075_4" type="fixed">
    <parent link="Root"/>
    <child link="plate_4_4_4075_4"/>
    <origin xyz="1.240000000000e-01 1.240000000000e-01 0.000000000000e+00" rpy="0.000000000000e+00 -0.000000000000e+00 -1.570796326795e+00"/>
  </joint>
  <link name="plate_16_16_4075_3" >
    <visual><origin xyz="-6.000000000000e-02 -6.000000000000e-02 -1.600000000000e-03" rpy="0.000000000000e+00 -0.000000000000e+00 0.000000000000e+00"/><geometry><box size="1.280000000000e-01 1.280000000000e-01 3.200000000000e-03"/></geometry>
</visual>
    <collision><origin xyz="-6.000000000000e-02 -6.000000000000e-02 -1.600000000000e-03" rpy="0.000000000000e+00 -0.000000000000e+00 0.000000000000e+00"/><geometry><box size="1.280000000000e-01 1.280000000000e-01 3.200000000000e-03"/></geometry>
</collision>
    <inertial>
      <mass value="6.763320000000e-02"/>
      <origin xyz="-6.000000000000e-02 -6.000000000000e-02 -1.600000000000e-03"/>
      <inertia ixx="9.239950000000e-05" ixy="-3.256420127868e-36" ixz="0.000000000000e+00" iyy="9.239950000000e-05" iyz="0.000000000000e+00" izz="1.846840000000e-04"/>
    </inertial>
  </link>
  <joint name="plate_16_16_4075_3" type="fixed">
    <parent link="plate_4_4_4075_4"/>
    <child link="plate_16_16_4075_3"/>
    <origin xyz="-8.000000000000e-03 4.898587196589e-19 0.000000000000e+00" rpy="0.000000000000e+00 -0.000000000000e+00 0.000000000000e+00"/>
  </joint>
  <link name="plate_16_16_4075_2" >
    <visual><origin xyz="-6.000000000000e-02 -6.000000000000e-02 -1.600000000000e-03" rpy="0.000000000000e+00 -0.000000000000e+00 0.000000000000e+00"/><geometry><box size="1.280000000000e-01 1.280000000000e-01 3.200000000000e-03"/></geometry>
</visual>
    <collision><origin xyz="-6.000000000000e-02 -6.000000000000e-02 -1.600000000000e-03" rpy="0.000000000000e+00 -0.000000000000e+00 0.000000000000e+00"/><geometry><box size="1.280000000000e-01 1.280000000000e-01 3.200000000000e-03"/></geometry>
</collision>
    <inertial>
      <mass value="6.763320000000e-02"/>
      <origin xyz="-6.000000000000e-02 -6.000000000000e-02 -1.600000000000e-03"/>
      <inertia ixx="9.239950000000e-05" ixy="-3.256420127868e-36" ixz="0.000000000000e+00" iyy="9.239950000000e-05" iyz="0.000000000000e+00" izz="1.846840000000e-04"/>
    </inertial>
  </link>
  <joint name="plate_16_16_4075_2" type="fixed">
    <parent link="plate_4_4_4075_4"/>
    <child link="plate_16_16_4075_2"/>
    <origin xyz="4.898587196589e-19 8.000000000000e-03 0.000000000000e+00" rpy="0.000000000000e+00 -0.000000000000e+00 3.141592653590e+00"/>
  </joint>
  <link name="Frame_Bottom_Socket_3007_3" >
    <visual><geometry><mesh filename="file:///tmp/arm_robot3_Frame_Bottom_Socket_3007_3_vis.dae"/></geometry></visual>
    <visual><origin xyz="-4.000000000000e-03 -8.000000000000e-03 1.500000000000e-03" rpy="-0.000000000000e+00 -1.570796326795e+00 0.000000000000e+00"/><geometry><box size="3.000000000000e-03 2.400000000000e-02 3.200000000000e-02"/></geometry>
</visual>
    <collision><geometry><mesh filename="file:///tmp/arm_robot3_Frame_Bottom_Socket_3007_3_col.stl"/></geometry></collision>
    <collision><origin xyz="-4.000000000000e-03 -8.000000000000e-03 1.500000000000e-03" rpy="-0.000000000000e+00 -1.570796326795e+00 0.000000000000e+00"/><geometry><box size="3.000000000000e-03 2.400000000000e-02 3.200000000000e-02"/></geometry>
</collision>
    <inertial>
      <mass value="1.439500000000e-02"/>
      <origin xyz="-4.000000000000e-03 2.703300000000e-02 2.300000000000e-02"/>
      <inertia ixx="4.839380000000e-06" ixy="-7.402000000000e-18" ixz="-6.339590000000e-18" iyy="4.457940000000e-06" iyz="3.347000000000e-14" izz="2.187980000000e-06"/>
    </inertial>
  </link>
  <joint name="Frame_Bottom_Socket_3007_3" type="fixed">
    <parent link="Root"/>
    <child link="Frame_Bottom_Socket_3007_3"/>
    <origin xyz="6.800000000000e-02 6.000000000000e-02 0.000000000000e+00" rpy="0.000000000000e+00 -0.000000000000e+00 0.000000000000e+00"/>
  </joint>
  <link name="XL-430_2494_17" >
    <visual><geometry><mesh filename="file:///tmp/arm_robot3_XL-430_2494_17_vis.dae"/></geometry></visual>
    <collision><geometry><mesh filename="file:///tmp/arm_robot3_XL-430_2494_17_col.stl"/></geometry></collision>
    <inertial>
      <mass value="5.700000000000e-02"/>
      <origin xyz="1.058030000000e-02 -2.338720000000e-02 -1.852570000000e-02"/>
      <inertia ixx="1.549380000000e-05" ixy="1.751460000000e-07" ixz="-4.811160000000e-08" iyy="8.252850000000e-06" iyz="8.492440000000e-07" izz="1.374130000000e-05"/>
    </inertial>
  </link>
  <joint name="XL-430_2494_17" type="fixed">
    <parent link="Frame_Bottom_Socket_3007_3"/>
    <child link="XL-430_2494_17"/>
    <origin xyz="7.000000000000e-03 1.200000000000e-02 6.000000000000e-03" rpy="3.141592653590e+00 -1.224646799147e-16 3.141592653590e+00"/>
  </joint>
  <link name="LINK_0" >
    <visual><geometry><mesh filename="file:///tmp/arm_robot3_LINK_0_vis.dae"/></geometry></visual>
    <collision><geometry><mesh filename="file:///tmp/arm_robot3_LINK_0_col.stl"/></geometry></collision>
    <inertial>
      <mass value="5.695000000000e-03"/>
      <origin xyz="-6.586000000000e-08 -1.744500000000e-02 4.225000000000e-02"/>
      <inertia ixx="4.432520000000e-07" ixy="-5.271340000000e-35" ixz="-2.374000000000e-19" iyy="1.577090000000e-06" iyz="-6.855980000000e-23" izz="1.268320000000e-06"/>
    </inertial>
  </link>
  <joint name="servo1" type="revolute">
    <parent link="XL-430_2494_17"/>
    <child link="LINK_0"/>
    <origin xyz="1.100000000000e-02 -8.000000000000e-03 -3.600000000000e-02" rpy="3.141592653590e+00 -1.224646799147e-16 3.141592653590e+00"/>
    <axis xyz="0.000000000000e+00 0.000000000000e+00 1.000000000000e+00"/>
    <limit lower="-3.141592653590e+00" upper="3.141592653590e+00" velocity="1.797693134862e+308" effort="1.797693134862e+308"/>
  </joint>
  <xacro:gazebo_transmission joint_name="servo1"/>
  <link name="XL-430_2494_21" >
    <visual><geometry><mesh filename="file:///tmp/arm_robot3_XL-430_2494_21_vis.dae"/></geometry></visual>
    <collision><geometry><mesh filename="file:///tmp/arm_robot3_XL-430_2494_21_col.stl"/></geometry></collision>
    <inertial>
      <mass value="5.700000000000e-02"/>
      <origin xyz="1.661280000000e-02 -1.141970000000e-02 -1.547430000000e-02"/>
      <inertia ixx="8.252850000000e-06" ixy="1.751460000000e-07" ixz="-8.492440000000e-07" iyy="1.549380000000e-05" iyz="4.811160000000e-08" izz="1.374130000000e-05"/>
    </inertial>
  </link>
  <joint name="XL-430_2494_21" type="fixed">
    <parent link="LINK_0"/>
    <child link="XL-430_2494_21"/>
    <origin xyz="1.700000000000e-02 -1.120000000000e-02 1.020000000000e-02" rpy="-3.141592653584e+00 -1.570794912581e+00 -5.721033058801e-12"/>
  </joint>
  <link name="LINK_1" >
    <visual><geometry><mesh filename="file:///tmp/arm_robot3_LINK_1_vis.dae"/></geometry></visual>
    <visual><origin xyz="-2.806854541574e-17 5.130000000000e-02 -1.700000000000e-02" rpy="5.495323605390e-16 -1.570796326795e+00 0.000000000000e+00"/><geometry><box size="3.200000000000e-02 1.000000000000e-03 3.200000000000e-02"/></geometry>
</visual>
    <collision><geometry><mesh filename="file:///tmp/arm_robot3_LINK_1_col.stl"/></geometry></collision>
    <collision><origin xyz="-2.806854541574e-17 5.130000000000e-02 -1.700000000000e-02" rpy="5.495323605390e-16 -1.570796326795e+00 0.000000000000e+00"/><geometry><box size="3.200000000000e-02 1.000000000000e-03 3.200000000000e-02"/></geometry>
</collision>
    <inertial>
      <mass value="1.439500000000e-02"/>
      <origin xyz="-1.265740000000e-17 2.303300000000e-02 -1.900000000000e-02"/>
      <inertia ixx="4.839380000000e-06" ixy="-7.401790000000e-18" ixz="-6.338410000000e-18" iyy="4.457940000000e-06" iyz="3.347000000000e-14" izz="2.187980000000e-06"/>
    </inertial>
  </link>
  <joint name="servo2" type="revolute">
    <parent link="XL-430_2494_21"/>
    <child link="LINK_1"/>
    <origin xyz="3.200000000000e-02 -1.100000000000e-02 2.000000000000e-03" rpy="-2.545624115284e-16 -9.900800000000e-18 -1.570796326795e+00"/>
    <axis xyz="0.000000000000e+00 0.000000000000e+00 1.000000000000e+00"/>
    <limit lower="-3.141592653590e+00" upper="3.141592653590e+00" velocity="1.797693134862e+308" effort="1.797693134862e+308"/>
  </joint>
  <xacro:gazebo_transmission joint_name="servo2"/>
  <link name="Frame_Short_Socket_364_0" >
    <visual><geometry><mesh filename="file:///tmp/arm_robot3_Frame_Short_Socket_364_0_vis.dae"/></geometry></visual>
    <visual><origin xyz="-1.200000000000e-02 -1.200000000000e-02 1.500000000000e-03" rpy="1.570796326795e+00 -4.866409769750e-22 -1.871696065290e-22"/><geometry><box size="3.200000000000e-02 3.000000000000e-03 3.200000000000e-02"/></geometry>
</visual>
    <collision><geometry><mesh filename="file:///tmp/arm_robot3_Frame_Short_Socket_364_0_col.stl"/></geometry></collision>
    <collision><origin xyz="-1.200000000000e-02 -1.200000000000e-02 1.500000000000e-03" rpy="1.570796326795e+00 -4.866409769750e-22 -1.871696065290e-22"/><geometry><box size="3.200000000000e-02 3.000000000000e-03 3.200000000000e-02"/></geometry>
</collision>
    <inertial>
      <mass value="5.695000000000e-03"/>
      <origin xyz="-1.400010000000e-02 -2.944500000000e-02 4.425000000000e-02"/>
      <inertia ixx="4.432520000000e-07" ixy="2.122200000000e-28" ixz="-2.374000000000e-19" iyy="1.577090000000e-06" iyz="6.855980000000e-23" izz="1.268320000000e-06"/>
    </inertial>
  </link>
  <joint name="Frame_Short_Socket_364_0" type="fixed">
    <parent link="LINK_1"/>
    <child link="Frame_Short_Socket_364_0"/>
    <origin xyz="1.200000000000e-02 5.180000000000e-02 -5.000000000000e-03" rpy="-1.570796326795e+00 -1.570796326795e+00 0.000000000000e+00"/>
  </joint>
  <link name="XL-430_364_1" >
    <visual><geometry><mesh filename="file:///tmp/arm_robot3_XL-430_364_1_vis.dae"/></geometry></visual>
    <collision><geometry><mesh filename="file:///tmp/arm_robot3_XL-430_364_1_col.stl"/></geometry></collision>
    <inertial>
      <mass value="5.700000000000e-02"/>
      <origin xyz="1.661280000000e-02 -1.141970000000e-02 -1.547430000000e-02"/>
      <inertia ixx="8.252850000000e-06" ixy="1.751460000000e-07" ixz="-8.492440000000e-07" iyy="1.549380000000e-05" iyz="4.811160000000e-08" izz="1.374130000000e-05"/>
    </inertial>
  </link>
  <joint name="XL-430_364_1" type="fixed">
    <parent link="Frame_Short_Socket_364_0"/>
    <child link="XL-430_364_1"/>
    <origin xyz="3.000000000000e-03 -2.320000000000e-02 1.220000000000e-02" rpy="-3.141592653546e+00 -1.570794912581e+00 -4.420746029063e-11"/>
  </joint>
  <link name="LINK_2" >
    <visual><geometry><mesh filename="file:///tmp/arm_robot3_LINK_2_vis.dae"/></geometry></visual>
    <visual><origin xyz="8.177038992943e-18 5.130000000000e-02 -1.700000000000e-02" rpy="-1.570092458680e-16 -1.570796326795e+00 0.000000000000e+00"/><geometry><box size="3.200000000000e-02 1.000000000000e-03 3.200000000000e-02"/></geometry>
</visual>
    <collision><geometry><mesh filename="file:///tmp/arm_robot3_LINK_2_col.stl"/></geometry></collision>
    <collision><origin xyz="8.177038992943e-18 5.130000000000e-02 -1.700000000000e-02" rpy="-1.570092458680e-16 -1.570796326795e+00 0.000000000000e+00"/><geometry><box size="3.200000000000e-02 1.000000000000e-03 3.200000000000e-02"/></geometry>
</collision>
    <inertial>
      <mass value="1.439500000000e-02"/>
      <origin xyz="3.616390000000e-18 2.303300000000e-02 -1.900000000000e-02"/>
      <inertia ixx="4.839380000000e-06" ixy="-7.402060000000e-18" ixz="-6.338410000000e-18" iyy="4.457940000000e-06" iyz="3.347000000000e-14" izz="2.187980000000e-06"/>
    </inertial>
  </link>
  <joint name="servo3" type="revolute">
    <parent link="XL-430_364_1"/>
    <child link="LINK_2"/>
    <origin xyz="3.200000000000e-02 -1.100000000000e-02 2.000000000000e-03" rpy="-4.306205389558e-16 -1.178046000000e-16 -1.570796326795e+00"/>
    <axis xyz="0.000000000000e+00 0.000000000000e+00 1.000000000000e+00"/>
    <limit lower="-3.141592653590e+00" upper="3.141592653590e+00" velocity="1.797693134862e+308" effort="1.797693134862e+308"/>
  </joint>
  <xacro:gazebo_transmission joint_name="servo3"/>
  <link name="Hinge_Long_Socket_2922_2" >
    <visual><geometry><mesh filename="file:///tmp/arm_robot3_Hinge_Long_Socket_2922_2_vis.dae"/></geometry></visual>
    <visual><origin xyz="-1.200000000000e-02 -1.200000000000e-02 1.500000000000e-03" rpy="-1.570796326795e+00 5.989427408910e-22 -1.497356852230e-22"/><geometry><box size="3.200000000000e-02 3.000000000000e-03 3.200000000000e-02"/></geometry>
</visual>
    <collision><geometry><mesh filename="file:///tmp/arm_robot3_Hinge_Long_Socket_2922_2_col.stl"/></geometry></collision>
    <collision><origin xyz="-1.200000000000e-02 -1.200000000000e-02 1.500000000000e-03" rpy="-1.570796326795e+00 5.989427408910e-22 -1.497356852230e-22"/><geometry><box size="3.200000000000e-02 3.000000000000e-03 3.200000000000e-02"/></geometry>
</collision>
    <inertial>
      <mass value="1.439500000000e-02"/>
      <origin xyz="-1.400000000000e-02 -1.200000000000e-02 3.076700000000e-02"/>
      <inertia ixx="2.187980000000e-06" ixy="6.339000000000e-18" ixz="-3.347000000000e-14" iyy="4.839380000000e-06" iyz="-7.402080000000e-18" izz="4.457940000000e-06"/>
    </inertial>
  </link>
  <joint name="Hinge_Long_Socket_2922_2" type="fixed">
    <parent link="LINK_2"/>
    <child link="Hinge_Long_Socket_2922_2"/>
    <origin xyz="1.200000000000e-02 5.180000000000e-02 -5.000000000000e-03" rpy="-1.570796326795e+00 -1.570796326795e+00 0.000000000000e+00"/>
  </joint>
  <link name="LINK_3" >
    <visual><geometry><mesh filename="file:///tmp/arm_robot3_LINK_3_vis.dae"/></geometry></visual>
    <collision><geometry><mesh filename="file:///tmp/arm_robot3_LINK_3_col.stl"/></geometry></collision>
    <inertial>
      <mass value="5.700000000000e-02"/>
      <origin xyz="4.196610000000e-04 -1.538720000000e-02 -1.747430000000e-02"/>
      <inertia ixx="1.549380000000e-05" ixy="-1.751460000000e-07" ixz="-4.811160000000e-08" iyy="8.252850000000e-06" iyz="-8.492440000000e-07" izz="1.374130000000e-05"/>
    </inertial>
  </link>
  <joint name="servo4" type="revolute">
    <parent link="Hinge_Long_Socket_2922_2"/>
    <child link="LINK_3"/>
    <origin xyz="5.000000000000e-03 -1.200000000000e-02 5.380000000000e-02" rpy="-1.570796326795e+00 1.110223024625e-16 -1.570796326795e+00"/>
    <axis xyz="-0.000000000000e+00 -0.000000000000e+00 -1.000000000000e+00"/>
    <limit lower="-3.141592653590e+00" upper="3.141592653590e+00" velocity="1.797693134862e+308" effort="1.797693134862e+308"/>
  </joint>
  <xacro:gazebo_transmission joint_name="servo4"/>
  <link name="Frame_Short_Plug_2922_4" >
    <visual><geometry><mesh filename="file:///tmp/arm_robot3_Frame_Short_Plug_2922_4_vis.dae"/></geometry></visual>
    <visual><origin xyz="-9.700019209476e-03 -1.120000247115e-02 -1.499998573271e-02" rpy="-2.034444028876e+00 -1.570795284228e+00 4.636472358232e-01"/><geometry><box size="3.200000000000e-02 1.000000000000e-03 3.200000000000e-02"/></geometry>
</visual>
    <collision><geometry><mesh filename="file:///tmp/arm_robot3_Frame_Short_Plug_2922_4_col.stl"/></geometry></collision>
    <collision><origin xyz="-9.700019209476e-03 -1.120000247115e-02 -1.499998573271e-02" rpy="-2.034444028876e+00 -1.570795284228e+00 4.636472358232e-01"/><geometry><box size="3.200000000000e-02 1.000000000000e-03 3.200000000000e-02"/></geometry>
</collision>
    <inertial>
      <mass value="5.695000000000e-03"/>
      <origin xyz="3.205000000000e-02 6.244980000000e-03 -1.700010000000e-02"/>
      <inertia ixx="1.268320000000e-06" ixy="1.439620000000e-13" ixz="-7.693800000000e-13" iyy="1.577090000000e-06" iyz="-5.286520000000e-13" izz="4.432520000000e-07"/>
    </inertial>
  </link>
  <joint name="Frame_Short_Plug_2922_4" type="fixed">
    <parent link="LINK_3"/>
    <child link="Frame_Short_Plug_2922_4"/>
    <origin xyz="-1.100000000000e-02 -3.200000000000e-02 -2.000000000000e-03" rpy="1.177100000000e-16 5.899402365543e-16 1.570796326795e+00"/>
  </joint>
  <link name="plate_6_12_1879_10" >
    <visual><origin xyz="1.200000000000e-02 1.200000000000e-02 1.600000000000e-03" rpy="0.000000000000e+00 -0.000000000000e+00 0.000000000000e+00"/><geometry><box size="4.800000000000e-02 9.600000000000e-02 3.200000000000e-03"/></geometry>
</visual>
    <collision><origin xyz="1.200000000000e-02 1.200000000000e-02 1.600000000000e-03" rpy="0.000000000000e+00 -0.000000000000e+00 0.000000000000e+00"/><geometry><box size="4.800000000000e-02 9.600000000000e-02 3.200000000000e-03"/></geometry>
</collision>
    <inertial>
      <mass value="1.902180000000e-02"/>
      <origin xyz="1.200000000000e-02 1.200000000000e-02 1.600000000000e-03"/>
      <inertia ixx="1.462500000000e-05" ixy="0.000000000000e+00" ixz="0.000000000000e+00" iyy="3.668420000000e-06" iyz="0.000000000000e+00" izz="1.826100000000e-05"/>
    </inertial>
  </link>
  <joint name="plate_6_12_1879_10" type="fixed">
    <parent link="Frame_Short_Plug_2922_4"/>
    <child link="plate_6_12_1879_10"/>
    <origin xyz="-1.020000000000e-02 -2.320000000000e-02 -2.700000000000e-02" rpy="-2.610457156487e-01 -1.570794520261e+00 2.610452492087e-01"/>
  </joint>
  <link name="block_2_3_2709_0" >
    <visual><origin xyz="-4.000000000000e-03 -8.000000000000e-03 4.800000000000e-03" rpy="0.000000000000e+00 -0.000000000000e+00 0.000000000000e+00"/><geometry><box size="1.600000000000e-02 2.400000000000e-02 9.600000000000e-03"/></geometry>
</visual>
    <collision><origin xyz="-4.000000000000e-03 -8.000000000000e-03 4.800000000000e-03" rpy="0.000000000000e+00 -0.000000000000e+00 0.000000000000e+00"/><geometry><box size="1.600000000000e-02 2.400000000000e-02 9.600000000000e-03"/></geometry>
</collision>
    <inertial>
      <mass value="4.755460000000e-03"/>
      <origin xyz="-4.000000000000e-03 -8.000000000000e-03 4.800000000000e-03"/>
      <inertia ixx="2.647840000000e-07" ixy="0.000000000000e+00" ixz="0.000000000000e+00" iyy="1.379720000000e-07" iyz="0.000000000000e+00" izz="3.297120000000e-07"/>
    </inertial>
  </link>
  <joint name="block_2_3_2709_0" type="fixed">
    <parent link="plate_6_12_1879_10"/>
    <child link="block_2_3_2709_0"/>
    <origin xyz="-8.000000000000e-03 5.600000000000e-02 3.200000000000e-03" rpy="6.661338147751e-16 -1.213248584210e-21 1.570796326795e+00"/>
  </joint>
  <link name="block_2_3_2709_1" >
    <visual><origin xyz="-4.000000000000e-03 -8.000000000000e-03 4.800000000000e-03" rpy="0.000000000000e+00 -0.000000000000e+00 0.000000000000e+00"/><geometry><box size="1.600000000000e-02 2.400000000000e-02 9.600000000000e-03"/></geometry>
</visual>
    <collision><origin xyz="-4.000000000000e-03 -8.000000000000e-03 4.800000000000e-03" rpy="0.000000000000e+00 -0.000000000000e+00 0.000000000000e+00"/><geometry><box size="1.600000000000e-02 2.400000000000e-02 9.600000000000e-03"/></geometry>
</collision>
    <inertial>
      <mass value="4.755460000000e-03"/>
      <origin xyz="-4.000000000000e-03 -8.000000000000e-03 4.800000000000e-03"/>
      <inertia ixx="2.647840000000e-07" ixy="0.000000000000e+00" ixz="0.000000000000e+00" iyy="1.379720000000e-07" iyz="0.000000000000e+00" izz="3.297120000000e-07"/>
    </inertial>
  </link>
  <joint name="block_2_3_2709_1" type="fixed">
    <parent link="block_2_3_2709_0"/>
    <child link="block_2_3_2709_1"/>
    <origin xyz="7.385210122194e-17 2.110845809227e-18 9.600000000000e-03" rpy="6.661338147751e-16 -4.720947553626e-22 -4.711674083477e-22"/>
  </joint>
  <link name="grove-sensor-mounter_1879_12" >
    <visual><geometry><mesh filename="file:///tmp/arm_robot3_grove-sensor-mounter_1879_12_vis.dae"/></geometry></visual>
    <collision><geometry><mesh filename="file:///tmp/arm_robot3_grove-sensor-mounter_1879_12_col.stl"/></geometry></collision>
    <inertial>
      <mass value="6.297000000000e-03"/>
      <origin xyz="8.000000000000e-03 8.000000000000e-03 9.438000000000e-03"/>
      <inertia ixx="4.218150000000e-07" ixy="1.013000000000e-16" ixz="4.000000000000e-12" iyy="4.236440000000e-07" iyz="4.000000000000e-12" izz="6.508820000000e-07"/>
    </inertial>
  </link>
  <joint name="grove-sensor-mounter_1879_12" type="fixed">
    <parent link="block_2_3_2709_1"/>
    <child link="grove-sensor-mounter_1879_12"/>
    <origin xyz="1.834095329941e-17 9.049766182914e-18 9.600000000000e-03" rpy="-6.661338147751e-16 2.825480143626e-22 -3.141592653590e+00"/>
  </joint>
  <link name="grove-color-sensor_1879_11" >
    <visual><geometry><mesh filename="file:///tmp/arm_robot3_grove-color-sensor_1879_11_vis.dae"/></geometry></visual>
    <collision><geometry><mesh filename="file:///tmp/arm_robot3_grove-color-sensor_1879_11_col.stl"/></geometry></collision>
    <inertial>
      <mass value="2.945000000000e-03"/>
      <origin xyz="1.000000000000e-02 0.000000000000e+00 1.500000000000e-03"/>
      <inertia ixx="1.000000000000e-09" ixy="0.000000000000e+00" ixz="0.000000000000e+00" iyy="1.000000000000e-09" iyz="0.000000000000e+00" izz="1.000000000000e-09"/>
    </inertial>
  </link>
  <joint name="grove-color-sensor_1879_11" type="fixed">
    <parent link="grove-sensor-mounter_1879_12"/>
    <child link="grove-color-sensor_1879_11"/>
    <origin xyz="8.000000000000e-03 8.000000000000e-03 1.710000000000e-02" rpy="5.096700809227e-22 6.661338147751e-16 1.570796326795e+00"/>
  </joint>
  <link name="Fixed_Finger_3007_0" >
    <visual><geometry><mesh filename="file:///tmp/arm_robot3_Fixed_Finger_3007_0_vis.dae"/></geometry></visual>
    <collision><geometry><mesh filename="file:///tmp/arm_robot3_Fixed_Finger_3007_0_col.stl"/></geometry></collision>
    <inertial>
      <mass value="2.687200000000e-02"/>
      <origin xyz="1.200000000000e-02 -3.647900000000e-02 3.130600000000e-02"/>
      <inertia ixx="2.611760000000e-05" ixy="2.440000000000e-10" ixz="-3.100000000000e-10" iyy="2.425330000000e-05" iyz="5.836770000000e-06" izz="1.041190000000e-05"/>
    </inertial>
  </link>
  <joint name="Fixed_Finger_3007_0" type="fixed">
    <parent link="plate_6_12_1879_10"/>
    <child link="Fixed_Finger_3007_0"/>
    <origin xyz="1.317415985464e-17 -3.138217364908e-18 3.200000000000e-03" rpy="6.661338147751e-16 -1.213248584210e-21 1.570796326795e+00"/>
  </joint>
  <link name="XL-430_3007_1" >
    <visual><geometry><mesh filename="file:///tmp/arm_robot3_XL-430_3007_1_vis.dae"/></geometry></visual>
    <collision><geometry><mesh filename="file:///tmp/arm_robot3_XL-430_3007_1_col.stl"/></geometry></collision>
    <inertial>
      <mass value="5.700000000000e-02"/>
      <origin xyz="1.661280000000e-02 -1.141970000000e-02 -1.547430000000e-02"/>
      <inertia ixx="8.252850000000e-06" ixy="1.751460000000e-07" ixz="-8.492440000000e-07" iyy="1.549380000000e-05" iyz="4.811160000000e-08" izz="1.374130000000e-05"/>
    </inertial>
  </link>
  <joint name="XL-430_3007_1" type="fixed">
    <parent link="Fixed_Finger_3007_0"/>
    <child link="XL-430_3007_1"/>
    <origin xyz="2.900000000000e-02 -3.600000000000e-02 3.520000000000e-02" rpy="1.570796904145e+00 -5.773497054884e-07 1.570795172094e+00"/>
  </joint>
  <link name="LINK_4" >
    <visual><geometry><mesh filename="file:///tmp/arm_robot3_LINK_4_vis.dae"/></geometry></visual>
    <collision><geometry><mesh filename="file:///tmp/arm_robot3_LINK_4_col.stl"/></geometry></collision>
    <inertial>
      <mass value="2.395900000000e-02"/>
      <origin xyz="-3.774100000000e-02 7.046000000000e-03 -1.899900000000e-02"/>
      <inertia ixx="1.101960000000e-05" ixy="-6.014870000000e-06" ixz="-1.217000000000e-09" iyy="2.393560000000e-05" iyz="9.000000000000e-11" izz="2.092360000000e-05"/>
    </inertial>
  </link>
  <joint name="servo5" type="revolute">
    <parent link="XL-430_3007_1"/>
    <child link="LINK_4"/>
    <origin xyz="3.200000000000e-02 -1.100000000000e-02 2.000000000000e-03" rpy="-1.456129045669e-16 7.899393959537e-17 -1.570796326795e+00"/>
    <axis xyz="0.000000000000e+00 0.000000000000e+00 1.000000000000e+00"/>
    <limit lower="-3.141592653590e+00" upper="3.141592653590e+00" velocity="1.797693134862e+308" effort="1.797693134862e+308"/>
  </joint>
  <xacro:gazebo_transmission joint_name="servo5"/>
  <link name="plate_4_4_4075_5" >
    <visual><origin xyz="-4.000000000000e-03 -4.000000000000e-03 1.600000000000e-03" rpy="0.000000000000e+00 -0.000000000000e+00 0.000000000000e+00"/><geometry><box size="3.200000000000e-02 3.200000000000e-02 3.200000000000e-03"/></geometry>
</visual>
    <collision><origin xyz="-4.000000000000e-03 -4.000000000000e-03 1.600000000000e-03" rpy="0.000000000000e+00 -0.000000000000e+00 0.000000000000e+00"/><geometry><box size="3.200000000000e-02 3.200000000000e-02 3.200000000000e-03"/></geometry>
</collision>
    <inertial>
      <mass value="4.227070000000e-03"/>
      <origin xyz="-4.000000000000e-03 -4.000000000000e-03 1.600000000000e-03"/>
      <inertia ixx="3.643170000000e-07" ixy="0.000000000000e+00" ixz="0.000000000000e+00" iyy="3.643170000000e-07" iyz="0.000000000000e+00" izz="7.214200000000e-07"/>
    </inertial>
  </link>
  <joint name="plate_4_4_4075_5" type="fixed">
    <parent link="Root"/>
    <child link="plate_4_4_4075_5"/>
    <origin xyz="4.000000000000e-03 4.000000000000e-03 0.000000000000e+00" rpy="0.000000000000e+00 -0.000000000000e+00 0.000000000000e+00"/>
  </joint>
  <link name="plate_16_16_4075_1" >
    <visual><origin xyz="-6.000000000000e-02 6.000000000000e-02 -1.600000000000e-03" rpy="0.000000000000e+00 -0.000000000000e+00 0.000000000000e+00"/><geometry><box size="1.280000000000e-01 1.280000000000e-01 3.200000000000e-03"/></geometry>
</visual>
    <collision><origin xyz="-6.000000000000e-02 6.000000000000e-02 -1.600000000000e-03" rpy="0.000000000000e+00 -0.000000000000e+00 0.000000000000e+00"/><geometry><box size="1.280000000000e-01 1.280000000000e-01 3.200000000000e-03"/></geometry>
</collision>
    <inertial>
      <mass value="6.763320000000e-02"/>
      <origin xyz="-6.000000000000e-02 6.000000000000e-02 -1.600000000000e-03"/>
      <inertia ixx="9.239950000000e-05" ixy="3.256420127868e-36" ixz="0.000000000000e+00" iyy="9.239950000000e-05" iyz="0.000000000000e+00" izz="1.846840000000e-04"/>
    </inertial>
  </link>
  <joint name="plate_16_16_4075_1" type="fixed">
    <parent link="plate_4_4_4075_5"/>
    <child link="plate_16_16_4075_1"/>
    <origin xyz="-8.000000000000e-03 0.000000000000e+00 0.000000000000e+00" rpy="0.000000000000e+00 -0.000000000000e+00 0.000000000000e+00"/>
  </joint>
  <link name="plate_16_16_4075_0" >
    <visual><origin xyz="6.000000000000e-02 6.000000000000e-02 -1.600000000000e-03" rpy="0.000000000000e+00 -0.000000000000e+00 0.000000000000e+00"/><geometry><box size="1.280000000000e-01 1.280000000000e-01 3.200000000000e-03"/></geometry>
</visual>
    <collision><origin xyz="6.000000000000e-02 6.000000000000e-02 -1.600000000000e-03" rpy="0.000000000000e+00 -0.000000000000e+00 0.000000000000e+00"/><geometry><box size="1.280000000000e-01 1.280000000000e-01 3.200000000000e-03"/></geometry>
</collision>
    <inertial>
      <mass value="6.763320000000e-02"/>
      <origin xyz="6.000000000000e-02 6.000000000000e-02 -1.600000000000e-03"/>
      <inertia ixx="9.239950000000e-05" ixy="-3.256420127868e-36" ixz="0.000000000000e+00" iyy="9.239950000000e-05" iyz="0.000000000000e+00" izz="1.846840000000e-04"/>
    </inertial>
  </link>
  <joint name="plate_16_16_4075_0" type="fixed">
    <parent link="plate_4_4_4075_5"/>
    <child link="plate_16_16_4075_0"/>
    <origin xyz="0.000000000000e+00 -8.000000000000e-03 0.000000000000e+00" rpy="0.000000000000e+00 -0.000000000000e+00 -1.570796326795e+00"/>
  </joint>
</robot>
