<?xml version="1.0" ?>
<!-- This file was generated by robot assembler -->
<robot name="AssembleRobot"
       xmlns:xi="http://www.w3.org/2001/XInclude"
       xmlns:gazebo="http://playerstage.sourceforge.net/gazebo/xmlschema/#gz"
       xmlns:model="http://playerstage.sourceforge.net/gazebo/xmlschema/#model"
       xmlns:sensor="http://playerstage.sourceforge.net/gazebo/xmlschema/#sensor"
       xmlns:body="http://playerstage.sourceforge.net/gazebo/xmlschema/#body"
       xmlns:geom="http://playerstage.sourceforge.net/gazebo/xmlschema/#geom"
       xmlns:joint="http://playerstage.sourceforge.net/gazebo/xmlschema/#joint"
       xmlns:interface="http://playerstage.sourceforge.net/gazebo/xmlschema/#interface"
       xmlns:rendering="http://playerstage.sourceforge.net/gazebo/xmlschema/#rendering"
       xmlns:renderable="http://playerstage.sourceforge.net/gazebo/xmlschema/#renderable"
       xmlns:controller="http://playerstage.sourceforge.net/gazebo/xmlschema/#controller"
       xmlns:physics="http://playerstage.sourceforge.net/gazebo/xmlschema/#physics"
       xmlns:xacro="http://www.ros.org/wiki/xacro">
  <xacro:macro name="gazebo_link_reference" params="link_name mu1:=0.9 mu2:=0.9" >
    <gazebo reference="${link_name}">
      <mu1>${mu1}</mu1>
      <mu2>${mu2}</mu2>
    </gazebo>
  </xacro:macro>
  <xacro:macro name="gazebo_transmission" params="joint_name" >
    <transmission name="${joint_name}_trans">
      <type>transmission_interface/SimpleTransmission</type>
      <joint name="${joint_name}">
        <hardwareInterface>hardware_interface/PositionJointInterface</hardwareInterface>
        <!--<hardwareInterface>hardware_interface/VelocityJointInterface</hardwareInterface-->
        <!--hardwareInterface>hardware_interface/EffortJointInterface</hardwareInterface-->
      </joint>
      <actuator name="${joint_name}_motor">
        <hardwareInterface>hardware_interface/PositionJointInterface</hardwareInterface>
        <!--<hardwareInterface>hardware_interface/VelocityJointInterface</hardwareInterface-->
        <!--hardwareInterface>hardware_interface/EffortJointInterface</hardwareInterface-->
        <mechanicalReduction>1</mechanicalReduction>
      </actuator>
    </transmission>
  </xacro:macro>
  <xacro:macro name="no_gazebo_transmission" params="joint_name" >
    <!-- dummy for fixed joint -->
  </xacro:macro>
  <link name="Root" >
    <visual><geometry><mesh filename="file:///tmp/AssembleRobot_Root_vis.dae"/></geometry></visual>
    <collision><geometry><mesh filename="file:///tmp/AssembleRobot_Root_col.stl"/></geometry></collision>
    <inertial>
      <mass value="2.286900000000e-02"/>
      <origin xyz="1.499000000000e-13 0.000000000000e+00 2.576000000000e-03"/>
      <inertia ixx="1.785610000000e-05" ixy="5.720000000000e-19" ixz="1.173000000000e-18" iyy="1.785610000000e-05" iyz="-1.392000000000e-19" izz="3.565130000000e-05"/>
    </inertial>
  </link>
  <link name="FR12_S102_P_213_4" >
    <visual><geometry><mesh filename="file:///tmp/AssembleRobot_FR12_S102_P_213_4_vis.dae"/></geometry></visual>
    <collision><geometry><mesh filename="file:///tmp/AssembleRobot_FR12_S102_P_213_4_col.stl"/></geometry></collision>
    <inertial>
      <mass value="9.852000000000e-03"/>
      <origin xyz="1.200000000000e-02 8.000000000000e-03 -4.616000000000e-03"/>
      <inertia ixx="6.999420000000e-07" ixy="0.000000000000e+00" ixz="6.952000000000e-19" iyy="1.667410000000e-06" iyz="0.000000000000e+00" izz="2.086850000000e-06"/>
    </inertial>
  </link>
  <joint name="FR12_S102_P_213_4" type="fixed">
    <parent link="Root"/>
    <child link="FR12_S102_P_213_4"/>
    <origin xyz="8.000000000000e-03 -4.800000000000e-02 0.000000000000e+00" rpy="0.000000000000e+00 -0.000000000000e+00 1.570796326795e+00"/>
  </joint>
  <link name="XL-430_213_5" >
    <visual><geometry><mesh filename="file:///tmp/AssembleRobot_XL-430_213_5_vis.dae"/></geometry></visual>
    <collision><geometry><mesh filename="file:///tmp/AssembleRobot_XL-430_213_5_col.stl"/></geometry></collision>
    <inertial>
      <mass value="5.700000000000e-02"/>
      <origin xyz="1.661280000000e-02 -1.141970000000e-02 -1.547430000000e-02"/>
      <inertia ixx="8.252850000000e-06" ixy="1.751460000000e-07" ixz="-8.492440000000e-07" iyy="1.549380000000e-05" iyz="4.811160000000e-08" izz="1.374130000000e-05"/>
    </inertial>
  </link>
  <joint name="XL-430_213_5" type="fixed">
    <parent link="FR12_S102_P_213_4"/>
    <child link="XL-430_213_5"/>
    <origin xyz="-5.000000000000e-03 -3.000000000000e-03 -1.320000000000e-02" rpy="3.141592653585e+00 1.570776527811e+00 -4.373696624297e-12"/>
  </joint>
  <link name="LINK_0" >
    <visual><geometry><mesh filename="file:///tmp/AssembleRobot_LINK_0_vis.dae"/></geometry></visual>
    <collision><geometry><mesh filename="file:///tmp/AssembleRobot_LINK_0_col.stl"/></geometry></collision>
    <inertial>
      <mass value="5.733000000000e-03"/>
      <origin xyz="-1.800000000000e-05 1.700000000000e-05 1.291500000000e-02"/>
      <inertia ixx="5.924300000000e-07" ixy="4.360000000000e-10" ixz="6.570000000000e-10" iyy="5.924600000000e-07" iyz="-6.350000000000e-10" izz="1.839640000000e-07"/>
    </inertial>
  </link>
  <joint name="LINK_0" type="revolute">
    <parent link="XL-430_213_5"/>
    <child link="LINK_0"/>
    <origin xyz="3.200000000000e-02 -1.100000000000e-02 2.000000000000e-03" rpy="7.121209275474e-16 1.570090000000e-16 -1.570796326795e+00"/>
    <axis xyz="0.000000000000e+00 0.000000000000e+00 1.000000000000e+00"/>
    <limit lower="-3.141592653590e+10" upper="3.141592653590e+10" velocity="1.797693134862e+308" effort="1.797693134862e+308"/>
  </joint>
  <xacro:gazebo_transmission joint_name="LINK_0"/>
  <link name="omni-wheel_213_17" >
    <visual><geometry><mesh filename="file:///tmp/AssembleRobot_omni-wheel_213_17_vis.dae"/></geometry></visual>
    <collision><geometry><mesh filename="file:///tmp/AssembleRobot_omni-wheel_213_17_col.stl"/></geometry></collision>
    <inertial>
      <mass value="5.479700000000e-02"/>
      <origin xyz="2.725000000000e-12 3.469450000000e-18 -1.255000000000e-02"/>
      <inertia ixx="1.126680000000e-05" ixy="0.000000000000e+00" ixz="-1.582000000000e-18" iyy="1.126680000000e-05" iyz="0.000000000000e+00" izz="1.680300000000e-05"/>
    </inertial>
  </link>
  <joint name="omni-wheel_213_17" type="fixed">
    <parent link="LINK_0"/>
    <child link="omni-wheel_213_17"/>
    <origin xyz="5.045021919690e-33 1.872705143085e-17 3.000000000000e-02" rpy="5.551115123126e-16 -1.232595164408e-31 -7.395570986447e-32"/>
  </joint>
  <link name="block_1_3_213_39" >
    <visual><origin xyz="0.000000000000e+00 8.000000000000e-03 4.800000000000e-03" rpy="0.000000000000e+00 -0.000000000000e+00 0.000000000000e+00"/><geometry><box size="8.000000000000e-03 2.400000000000e-02 9.600000000000e-03"/></geometry>
</visual>
    <collision><origin xyz="0.000000000000e+00 8.000000000000e-03 4.800000000000e-03" rpy="0.000000000000e+00 -0.000000000000e+00 0.000000000000e+00"/><geometry><box size="8.000000000000e-03 2.400000000000e-02 9.600000000000e-03"/></geometry>
</collision>
    <inertial>
      <mass value="2.377730000000e-03"/>
      <origin xyz="-3.469450000000e-18 8.000000000000e-03 4.800000000000e-03"/>
      <inertia ixx="1.323920000000e-07" ixy="0.000000000000e+00" ixz="0.000000000000e+00" iyy="3.094220000000e-08" iyz="0.000000000000e+00" izz="1.268120000000e-07"/>
    </inertial>
  </link>
  <joint name="block_1_3_213_39" type="fixed">
    <parent link="Root"/>
    <child link="block_1_3_213_39"/>
    <origin xyz="8.000000000000e-03 4.800000000000e-02 3.200000000000e-03" rpy="0.000000000000e+00 -0.000000000000e+00 1.570796326795e+00"/>
  </joint>
  <link name="block_1_3_213_40" >
    <visual><origin xyz="0.000000000000e+00 8.000000000000e-03 4.800000000000e-03" rpy="0.000000000000e+00 -0.000000000000e+00 0.000000000000e+00"/><geometry><box size="8.000000000000e-03 2.400000000000e-02 9.600000000000e-03"/></geometry>
</visual>
    <collision><origin xyz="0.000000000000e+00 8.000000000000e-03 4.800000000000e-03" rpy="0.000000000000e+00 -0.000000000000e+00 0.000000000000e+00"/><geometry><box size="8.000000000000e-03 2.400000000000e-02 9.600000000000e-03"/></geometry>
</collision>
    <inertial>
      <mass value="2.377730000000e-03"/>
      <origin xyz="-3.469450000000e-18 8.000000000000e-03 4.800000000000e-03"/>
      <inertia ixx="1.323920000000e-07" ixy="0.000000000000e+00" ixz="0.000000000000e+00" iyy="3.094220000000e-08" iyz="0.000000000000e+00" izz="1.268120000000e-07"/>
    </inertial>
  </link>
  <joint name="block_1_3_213_40" type="fixed">
    <parent link="block_1_3_213_39"/>
    <child link="block_1_3_213_40"/>
    <origin xyz="0.000000000000e+00 0.000000000000e+00 9.600000000000e-03" rpy="0.000000000000e+00 -0.000000000000e+00 0.000000000000e+00"/>
  </joint>
  <link name="block_1_3_213_41" >
    <visual><origin xyz="0.000000000000e+00 8.000000000000e-03 4.800000000000e-03" rpy="0.000000000000e+00 -0.000000000000e+00 0.000000000000e+00"/><geometry><box size="8.000000000000e-03 2.400000000000e-02 9.600000000000e-03"/></geometry>
</visual>
    <collision><origin xyz="0.000000000000e+00 8.000000000000e-03 4.800000000000e-03" rpy="0.000000000000e+00 -0.000000000000e+00 0.000000000000e+00"/><geometry><box size="8.000000000000e-03 2.400000000000e-02 9.600000000000e-03"/></geometry>
</collision>
    <inertial>
      <mass value="2.377730000000e-03"/>
      <origin xyz="-3.469450000000e-18 8.000000000000e-03 4.800000000000e-03"/>
      <inertia ixx="1.323920000000e-07" ixy="0.000000000000e+00" ixz="0.000000000000e+00" iyy="3.094220000000e-08" iyz="0.000000000000e+00" izz="1.268120000000e-07"/>
    </inertial>
  </link>
  <joint name="block_1_3_213_41" type="fixed">
    <parent link="block_1_3_213_40"/>
    <child link="block_1_3_213_41"/>
    <origin xyz="0.000000000000e+00 0.000000000000e+00 9.600000000000e-03" rpy="0.000000000000e+00 -0.000000000000e+00 0.000000000000e+00"/>
  </joint>
  <link name="block_1_3_213_42" >
    <visual><origin xyz="0.000000000000e+00 8.000000000000e-03 4.800000000000e-03" rpy="0.000000000000e+00 -0.000000000000e+00 0.000000000000e+00"/><geometry><box size="8.000000000000e-03 2.400000000000e-02 9.600000000000e-03"/></geometry>
</visual>
    <collision><origin xyz="0.000000000000e+00 8.000000000000e-03 4.800000000000e-03" rpy="0.000000000000e+00 -0.000000000000e+00 0.000000000000e+00"/><geometry><box size="8.000000000000e-03 2.400000000000e-02 9.600000000000e-03"/></geometry>
</collision>
    <inertial>
      <mass value="2.377730000000e-03"/>
      <origin xyz="-3.469450000000e-18 8.000000000000e-03 4.800000000000e-03"/>
      <inertia ixx="1.323920000000e-07" ixy="0.000000000000e+00" ixz="0.000000000000e+00" iyy="3.094220000000e-08" iyz="0.000000000000e+00" izz="1.268120000000e-07"/>
    </inertial>
  </link>
  <joint name="block_1_3_213_42" type="fixed">
    <parent link="block_1_3_213_41"/>
    <child link="block_1_3_213_42"/>
    <origin xyz="0.000000000000e+00 0.000000000000e+00 9.600000000000e-03" rpy="0.000000000000e+00 -0.000000000000e+00 0.000000000000e+00"/>
  </joint>
  <link name="block_1_3_213_43" >
    <visual><origin xyz="0.000000000000e+00 8.000000000000e-03 4.800000000000e-03" rpy="0.000000000000e+00 -0.000000000000e+00 0.000000000000e+00"/><geometry><box size="8.000000000000e-03 2.400000000000e-02 9.600000000000e-03"/></geometry>
</visual>
    <collision><origin xyz="0.000000000000e+00 8.000000000000e-03 4.800000000000e-03" rpy="0.000000000000e+00 -0.000000000000e+00 0.000000000000e+00"/><geometry><box size="8.000000000000e-03 2.400000000000e-02 9.600000000000e-03"/></geometry>
</collision>
    <inertial>
      <mass value="2.377730000000e-03"/>
      <origin xyz="-3.469450000000e-18 8.000000000000e-03 4.800000000000e-03"/>
      <inertia ixx="1.323920000000e-07" ixy="0.000000000000e+00" ixz="0.000000000000e+00" iyy="3.094220000000e-08" iyz="0.000000000000e+00" izz="1.268120000000e-07"/>
    </inertial>
  </link>
  <joint name="block_1_3_213_43" type="fixed">
    <parent link="block_1_3_213_42"/>
    <child link="block_1_3_213_43"/>
    <origin xyz="0.000000000000e+00 0.000000000000e+00 9.600000000000e-03" rpy="0.000000000000e+00 -0.000000000000e+00 0.000000000000e+00"/>
  </joint>
  <link name="vehicle-base-ps_213_44" >
    <visual><geometry><mesh filename="file:///tmp/AssembleRobot_vehicle-base-ps_213_44_vis.dae"/></geometry></visual>
    <collision><geometry><mesh filename="file:///tmp/AssembleRobot_vehicle-base-ps_213_44_col.stl"/></geometry></collision>
    <inertial>
      <mass value="2.286900000000e-02"/>
      <origin xyz="-8.000000000000e-03 -4.800000000000e-02 2.576000000000e-03"/>
      <inertia ixx="1.785610000000e-05" ixy="5.720000000000e-19" ixz="1.173000000000e-18" iyy="1.785610000000e-05" iyz="-1.392000000000e-19" izz="3.565130000000e-05"/>
    </inertial>
  </link>
  <joint name="vehicle-base-ps_213_44" type="fixed">
    <parent link="block_1_3_213_43"/>
    <child link="vehicle-base-ps_213_44"/>
    <origin xyz="0.000000000000e+00 0.000000000000e+00 9.600000000000e-03" rpy="0.000000000000e+00 -0.000000000000e+00 -1.570796326795e+00"/>
  </joint>
  <link name="Bottom_mounter_213_18" >
    <visual><geometry><mesh filename="file:///tmp/AssembleRobot_Bottom_mounter_213_18_vis.dae"/></geometry></visual>
    <collision><geometry><mesh filename="file:///tmp/AssembleRobot_Bottom_mounter_213_18_col.stl"/></geometry></collision>
    <inertial>
      <mass value="6.134000000000e-03"/>
      <origin xyz="-4.021000000000e-12 -3.469450000000e-18 4.519000000000e-03"/>
      <inertia ixx="1.103510000000e-06" ixy="1.972000000000e-16" ixz="9.333000000000e-17" iyy="4.426000000000e-07" iyz="-6.734000000000e-17" izz="1.517450000000e-06"/>
    </inertial>
  </link>
  <joint name="Bottom_mounter_213_18" type="fixed">
    <parent link="vehicle-base-ps_213_44"/>
    <child link="Bottom_mounter_213_18"/>
    <origin xyz="-8.000000000000e-03 -1.600000000000e-02 3.200000000000e-03" rpy="0.000000000000e+00 -0.000000000000e+00 0.000000000000e+00"/>
  </joint>
  <link name="XL-430_213_19" >
    <visual><geometry><mesh filename="file:///tmp/AssembleRobot_XL-430_213_19_vis.dae"/></geometry></visual>
    <collision><geometry><mesh filename="file:///tmp/AssembleRobot_XL-430_213_19_col.stl"/></geometry></collision>
    <inertial>
      <mass value="5.700000000000e-02"/>
      <origin xyz="1.058030000000e-02 -2.338720000000e-02 -1.852570000000e-02"/>
      <inertia ixx="1.549380000000e-05" ixy="1.751460000000e-07" ixz="-4.811160000000e-08" iyy="8.252850000000e-06" iyz="8.492440000000e-07" izz="1.374130000000e-05"/>
    </inertial>
  </link>
  <joint name="XL-430_213_19" type="fixed">
    <parent link="Bottom_mounter_213_18"/>
    <child link="XL-430_213_19"/>
    <origin xyz="1.100000000000e-02 2.000000000000e-02 6.200000000000e-03" rpy="3.141592653590e+00 1.224646799147e-16 3.141592653590e+00"/>
  </joint>
  <link name="LINK_1" >
    <visual><geometry><mesh filename="file:///tmp/AssembleRobot_LINK_1_vis.dae"/></geometry></visual>
    <collision><geometry><mesh filename="file:///tmp/AssembleRobot_LINK_1_col.stl"/></geometry></collision>
    <inertial>
      <mass value="5.695000000000e-03"/>
      <origin xyz="-6.586000000000e-08 2.136400000000e-18 3.555000000000e-03"/>
      <inertia ixx="4.432520000000e-07" ixy="2.374000000000e-19" ixz="2.907310000000e-35" iyy="1.268320000000e-06" iyz="-3.781290000000e-23" izz="1.577090000000e-06"/>
    </inertial>
  </link>
  <joint name="LINK_1" type="revolute">
    <parent link="XL-430_213_19"/>
    <child link="LINK_1"/>
    <origin xyz="1.100000000000e-02 -8.000000000000e-03 -3.600000000000e-02" rpy="3.141592653590e+00 -1.224646799147e-16 3.141592653590e+00"/>
    <axis xyz="0.000000000000e+00 0.000000000000e+00 1.000000000000e+00"/>
    <limit lower="-3.141592653590e+10" upper="3.141592653590e+10" velocity="1.797693134862e+308" effort="1.797693134862e+308"/>
  </joint>
  <xacro:gazebo_transmission joint_name="LINK_1"/>
  <link name="XL-430_213_21" >
    <visual><geometry><mesh filename="file:///tmp/AssembleRobot_XL-430_213_21_vis.dae"/></geometry></visual>
    <collision><geometry><mesh filename="file:///tmp/AssembleRobot_XL-430_213_21_col.stl"/></geometry></collision>
    <inertial>
      <mass value="5.700000000000e-02"/>
      <origin xyz="1.661280000000e-02 -1.141970000000e-02 -1.547430000000e-02"/>
      <inertia ixx="8.252850000000e-06" ixy="1.751460000000e-07" ixz="-8.492440000000e-07" iyy="1.549380000000e-05" iyz="4.811160000000e-08" izz="1.374130000000e-05"/>
    </inertial>
  </link>
  <joint name="XL-430_213_21" type="fixed">
    <parent link="LINK_1"/>
    <child link="XL-430_213_21"/>
    <origin xyz="1.700000000000e-02 -1.100000000000e-02 1.000000000000e-02" rpy="3.141592653590e+00 -1.570796326795e+00 0.000000000000e+00"/>
  </joint>
  <link name="LINK_2" >
    <visual><geometry><mesh filename="file:///tmp/AssembleRobot_LINK_2_vis.dae"/></geometry></visual>
    <collision><geometry><mesh filename="file:///tmp/AssembleRobot_LINK_2_col.stl"/></geometry></collision>
    <inertial>
      <mass value="1.439500000000e-02"/>
      <origin xyz="-3.616390000000e-18 2.303300000000e-02 -1.900000000000e-02"/>
      <inertia ixx="4.839380000000e-06" ixy="-7.401940000000e-18" ixz="-6.337820000000e-18" iyy="4.457940000000e-06" iyz="3.347000000000e-14" izz="2.187980000000e-06"/>
    </inertial>
  </link>
  <joint name="LINK_2" type="revolute">
    <parent link="XL-430_213_21"/>
    <child link="LINK_2"/>
    <origin xyz="3.200000000000e-02 -1.100000000000e-02 2.000000000000e-03" rpy="-1.300702098501e-16 7.850500000000e-17 -1.570796326795e+00"/>
    <axis xyz="0.000000000000e+00 0.000000000000e+00 1.000000000000e+00"/>
    <limit lower="-3.141592653590e+10" upper="3.141592653590e+10" velocity="1.797693134862e+308" effort="1.797693134862e+308"/>
  </joint>
  <xacro:gazebo_transmission joint_name="LINK_2"/>
  <link name="FR12_H103_S_213_23" >
    <visual><geometry><mesh filename="file:///tmp/AssembleRobot_FR12_H103_S_213_23_vis.dae"/></geometry></visual>
    <collision><geometry><mesh filename="file:///tmp/AssembleRobot_FR12_H103_S_213_23_col.stl"/></geometry></collision>
    <inertial>
      <mass value="1.760900000000e-02"/>
      <origin xyz="-1.200000000000e-02 8.000000000000e-03 2.311100000000e-02"/>
      <inertia ixx="7.218640000000e-06" ixy="7.969000000000e-18" ixz="1.769460000000e-33" iyy="1.189420000000e-05" iyz="-7.555000000000e-15" izz="7.020740000000e-06"/>
    </inertial>
  </link>
  <joint name="FR12_H103_S_213_23" type="fixed">
    <parent link="LINK_2"/>
    <child link="FR12_H103_S_213_23"/>
    <origin xyz="-8.000000000000e-03 3.270000000000e-02 -7.000000000000e-03" rpy="-1.570796326795e+00 -1.570796326795e+00 0.000000000000e+00"/>
  </joint>
  <link name="LINK_3" >
    <visual><geometry><mesh filename="file:///tmp/AssembleRobot_LINK_3_vis.dae"/></geometry></visual>
    <collision><geometry><mesh filename="file:///tmp/AssembleRobot_LINK_3_col.stl"/></geometry></collision>
    <inertial>
      <mass value="5.700000000000e-02"/>
      <origin xyz="4.196610000000e-04 -1.538720000000e-02 -1.747430000000e-02"/>
      <inertia ixx="1.549380000000e-05" ixy="-1.751460000000e-07" ixz="-4.811160000000e-08" iyy="8.252850000000e-06" iyz="-8.492440000000e-07" izz="1.374130000000e-05"/>
    </inertial>
  </link>
  <joint name="LINK_3" type="revolute">
    <parent link="FR12_H103_S_213_23"/>
    <child link="LINK_3"/>
    <origin xyz="7.000000000000e-03 8.000000000000e-03 5.920000000000e-02" rpy="-1.570796326795e+00 1.110223024625e-16 -1.570796326795e+00"/>
    <axis xyz="-0.000000000000e+00 -0.000000000000e+00 -1.000000000000e+00"/>
    <limit lower="-3.141592653590e+10" upper="3.141592653590e+10" velocity="1.797693134862e+308" effort="1.797693134862e+308"/>
  </joint>
  <xacro:gazebo_transmission joint_name="LINK_3"/>
  <link name="FR12_S102_P_213_25" >
    <visual><geometry><mesh filename="file:///tmp/AssembleRobot_FR12_S102_P_213_25_vis.dae"/></geometry></visual>
    <collision><geometry><mesh filename="file:///tmp/AssembleRobot_FR12_S102_P_213_25_col.stl"/></geometry></collision>
    <inertial>
      <mass value="9.852000000000e-03"/>
      <origin xyz="-8.584000000000e-03 -1.100000000000e-02 -1.700000000000e-02"/>
      <inertia ixx="2.086850000000e-06" ixy="-1.462290000000e-38" ixz="-6.955080000000e-19" iyy="1.667410000000e-06" iyz="3.372880000000e-38" izz="6.999420000000e-07"/>
    </inertial>
  </link>
  <joint name="FR12_S102_P_213_25" type="fixed">
    <parent link="LINK_3"/>
    <child link="FR12_S102_P_213_25"/>
    <origin xyz="-1.100000000000e-02 -3.200000000000e-02 -2.000000000000e-03" rpy="-7.850460000000e-17 -4.440892098501e-16 1.570796326795e+00"/>
  </joint>
  <link name="Fixed_Finger_213_26" >
    <visual><geometry><mesh filename="file:///tmp/AssembleRobot_Fixed_Finger_213_26_vis.dae"/></geometry></visual>
    <collision><geometry><mesh filename="file:///tmp/AssembleRobot_Fixed_Finger_213_26_col.stl"/></geometry></collision>
    <inertial>
      <mass value="2.687200000000e-02"/>
      <origin xyz="-1.200000000000e-02 -4.479000000000e-03 3.130600000000e-02"/>
      <inertia ixx="2.611760000000e-05" ixy="2.440000000000e-10" ixz="-3.100000000000e-10" iyy="2.425330000000e-05" iyz="5.836770000000e-06" izz="1.041190000000e-05"/>
    </inertial>
  </link>
  <joint name="Fixed_Finger_213_26" type="fixed">
    <parent link="FR12_S102_P_213_25"/>
    <child link="Fixed_Finger_213_26"/>
    <origin xyz="-1.320000000000e-02 -1.900000000000e-02 -2.900000000000e-02" rpy="1.570796326795e+00 -1.110223024625e-16 -1.570796326795e+00"/>
  </joint>
  <link name="XL-430_213_27" >
    <visual><geometry><mesh filename="file:///tmp/AssembleRobot_XL-430_213_27_vis.dae"/></geometry></visual>
    <collision><geometry><mesh filename="file:///tmp/AssembleRobot_XL-430_213_27_col.stl"/></geometry></collision>
    <inertial>
      <mass value="5.700000000000e-02"/>
      <origin xyz="1.661280000000e-02 -1.141970000000e-02 -1.547430000000e-02"/>
      <inertia ixx="8.252850000000e-06" ixy="1.751460000000e-07" ixz="-8.492440000000e-07" iyy="1.549380000000e-05" iyz="4.811160000000e-08" izz="1.374130000000e-05"/>
    </inertial>
  </link>
  <joint name="XL-430_213_27" type="fixed">
    <parent link="Fixed_Finger_213_26"/>
    <child link="XL-430_213_27"/>
    <origin xyz="5.000000000000e-03 -4.000000000000e-03 3.520000000000e-02" rpy="1.570796904145e+00 -5.773497043782e-07 1.570795172094e+00"/>
  </joint>
  <link name="LINK_4" >
    <visual><geometry><mesh filename="file:///tmp/AssembleRobot_LINK_4_vis.dae"/></geometry></visual>
    <collision><geometry><mesh filename="file:///tmp/AssembleRobot_LINK_4_col.stl"/></geometry></collision>
    <inertial>
      <mass value="2.395900000000e-02"/>
      <origin xyz="-3.774100000000e-02 7.046000000000e-03 -1.899900000000e-02"/>
      <inertia ixx="1.101960000000e-05" ixy="-6.014870000000e-06" ixz="-1.217000000000e-09" iyy="2.393560000000e-05" iyz="9.000000000000e-11" izz="2.092360000000e-05"/>
    </inertial>
  </link>
  <joint name="LINK_4" type="revolute">
    <parent link="XL-430_213_27"/>
    <child link="LINK_4"/>
    <origin xyz="3.200000000000e-02 -1.100000000000e-02 2.000000000000e-03" rpy="1.684066670566e-16 -3.920331988683e-16 -1.570796326795e+00"/>
    <axis xyz="0.000000000000e+00 0.000000000000e+00 1.000000000000e+00"/>
    <limit lower="-3.141592653590e+10" upper="3.141592653590e+10" velocity="1.797693134862e+308" effort="1.797693134862e+308"/>
  </joint>
  <xacro:gazebo_transmission joint_name="LINK_4"/>
  <link name="angle_2_2_5635_0" >
    <visual><geometry><mesh filename="file:///tmp/AssembleRobot_angle_2_2_5635_0_vis.dae"/></geometry></visual>
    <collision><geometry><mesh filename="file:///tmp/AssembleRobot_angle_2_2_5635_0_col.stl"/></geometry></collision>
    <inertial>
      <mass value="1.889000000000e-03"/>
      <origin xyz="4.000000000000e-03 -2.958000000000e-03 7.922000000000e-03"/>
      <inertia ixx="1.169110000000e-07" ixy="-1.913000000000e-19" ixz="4.476000000000e-18" iyy="1.028120000000e-07" iyz="3.369600000000e-08" izz="9.647800000000e-08"/>
    </inertial>
  </link>
  <joint name="angle_2_2_5635_0" type="fixed">
    <parent link="vehicle-base-ps_213_44"/>
    <child link="angle_2_2_5635_0"/>
    <origin xyz="-8.000000000000e-03 -9.600000000000e-02 3.200000000000e-03" rpy="0.000000000000e+00 -0.000000000000e+00 0.000000000000e+00"/>
  </joint>
  <link name="sensor-mounter_5635_1" >
    <visual><geometry><mesh filename="file:///tmp/AssembleRobot_sensor-mounter_5635_1_vis.dae"/></geometry></visual>
    <collision><geometry><mesh filename="file:///tmp/AssembleRobot_sensor-mounter_5635_1_col.stl"/></geometry></collision>
    <inertial>
      <mass value="3.584000000000e-03"/>
      <origin xyz="8.001000000000e-03 8.001000000000e-03 5.658000000000e-03"/>
      <inertia ixx="2.058560000000e-07" ixy="2.600000000000e-11" ixz="3.000000000000e-12" iyy="2.158660000000e-07" iyz="4.000000000000e-12" izz="3.426970000000e-07"/>
    </inertial>
  </link>
  <joint name="sensor-mounter_5635_1" type="fixed">
    <parent link="angle_2_2_5635_0"/>
    <child link="sensor-mounter_5635_1"/>
    <origin xyz="0.000000000000e+00 -7.100000000000e-03 7.200000000000e-03" rpy="1.570796326795e+00 -0.000000000000e+00 0.000000000000e+00"/>
  </joint>
  <link name="tof-sensor_5635_2" >
    <visual><geometry><mesh filename="file:///tmp/AssembleRobot_tof-sensor_5635_2_vis.dae"/></geometry></visual>
    <collision><geometry><mesh filename="file:///tmp/AssembleRobot_tof-sensor_5635_2_col.stl"/></geometry></collision>
    <inertial>
      <mass value="1.000000000000e-03"/>
      <origin xyz="-1.190000000000e-02 -1.190000000000e-02 0.000000000000e+00"/>
      <inertia ixx="1.000000000000e-09" ixy="0.000000000000e+00" ixz="0.000000000000e+00" iyy="1.000000000000e-09" iyz="0.000000000000e+00" izz="1.000000000000e-09"/>
    </inertial>
  </link>
  <joint name="tof-sensor_5635_2" type="fixed">
    <parent link="sensor-mounter_5635_1"/>
    <child link="tof-sensor_5635_2"/>
    <origin xyz="8.000000000000e-03 8.000000000000e-03 9.600000000000e-03" rpy="0.000000000000e+00 -0.000000000000e+00 0.000000000000e+00"/>
  </joint>
  <link name="FR12_S102_P_213_2" >
    <visual><geometry><mesh filename="file:///tmp/AssembleRobot_FR12_S102_P_213_2_vis.dae"/></geometry></visual>
    <collision><geometry><mesh filename="file:///tmp/AssembleRobot_FR12_S102_P_213_2_col.stl"/></geometry></collision>
    <inertial>
      <mass value="9.852000000000e-03"/>
      <origin xyz="-1.200000000000e-02 -8.000000000000e-03 -4.616000000000e-03"/>
      <inertia ixx="6.999420000000e-07" ixy="0.000000000000e+00" ixz="6.952000000000e-19" iyy="1.667410000000e-06" iyz="0.000000000000e+00" izz="2.086850000000e-06"/>
    </inertial>
  </link>
  <joint name="FR12_S102_P_213_2" type="fixed">
    <parent link="Root"/>
    <child link="FR12_S102_P_213_2"/>
    <origin xyz="-8.000000000000e-03 4.800000000000e-02 0.000000000000e+00" rpy="0.000000000000e+00 -0.000000000000e+00 1.570796326795e+00"/>
  </joint>
  <link name="XL-430_213_7" >
    <visual><geometry><mesh filename="file:///tmp/AssembleRobot_XL-430_213_7_vis.dae"/></geometry></visual>
    <collision><geometry><mesh filename="file:///tmp/AssembleRobot_XL-430_213_7_col.stl"/></geometry></collision>
    <inertial>
      <mass value="5.700000000000e-02"/>
      <origin xyz="1.661280000000e-02 -1.141970000000e-02 -1.547430000000e-02"/>
      <inertia ixx="8.252850000000e-06" ixy="1.751460000000e-07" ixz="-8.492440000000e-07" iyy="1.549380000000e-05" iyz="4.811160000000e-08" izz="1.374130000000e-05"/>
    </inertial>
  </link>
  <joint name="XL-430_213_7" type="fixed">
    <parent link="FR12_S102_P_213_2"/>
    <child link="XL-430_213_7"/>
    <origin xyz="5.000000000000e-03 3.000000000000e-03 -1.320000000000e-02" rpy="-0.000000000000e+00 1.570796326795e+00 0.000000000000e+00"/>
  </joint>
  <link name="LINK_5" >
    <visual><geometry><mesh filename="file:///tmp/AssembleRobot_LINK_5_vis.dae"/></geometry></visual>
    <collision><geometry><mesh filename="file:///tmp/AssembleRobot_LINK_5_col.stl"/></geometry></collision>
    <inertial>
      <mass value="5.733000000000e-03"/>
      <origin xyz="-1.800000000000e-05 1.700000000000e-05 1.291500000000e-02"/>
      <inertia ixx="5.924300000000e-07" ixy="4.360000000000e-10" ixz="6.570000000000e-10" iyy="5.924600000000e-07" iyz="-6.350000000000e-10" izz="1.839640000000e-07"/>
    </inertial>
  </link>
  <joint name="LINK_5" type="revolute">
    <parent link="XL-430_213_7"/>
    <child link="LINK_5"/>
    <origin xyz="3.200000000000e-02 -1.100000000000e-02 2.000000000000e-03" rpy="-1.648597000000e-15 7.850500000000e-17 -1.570796326795e+00"/>
    <axis xyz="0.000000000000e+00 0.000000000000e+00 1.000000000000e+00"/>
    <limit lower="-3.141592653590e+10" upper="3.141592653590e+10" velocity="1.797693134862e+308" effort="1.797693134862e+308"/>
  </joint>
  <xacro:gazebo_transmission joint_name="LINK_5"/>
  <link name="omni-wheel_213_15" >
    <visual><geometry><mesh filename="file:///tmp/AssembleRobot_omni-wheel_213_15_vis.dae"/></geometry></visual>
    <collision><geometry><mesh filename="file:///tmp/AssembleRobot_omni-wheel_213_15_col.stl"/></geometry></collision>
    <inertial>
      <mass value="5.479700000000e-02"/>
      <origin xyz="2.725000000000e-12 1.387780000000e-17 -1.255000000000e-02"/>
      <inertia ixx="1.126680000000e-05" ixy="-2.524350000000e-41" ixz="-1.582000000000e-18" iyy="1.126680000000e-05" iyz="-1.996760000000e-47" izz="1.680300000000e-05"/>
    </inertial>
  </link>
  <joint name="omni-wheel_213_15" type="fixed">
    <parent link="LINK_5"/>
    <child link="omni-wheel_213_15"/>
    <origin xyz="-1.648038893364e-33 9.513175260716e-19 3.000000000000e-02" rpy="-1.554311692010e-15 -8.194292652983e-29 5.047477198250e-29"/>
  </joint>
  <link name="block_1_3_213_34" >
    <visual><origin xyz="0.000000000000e+00 -8.000000000000e-03 4.800000000000e-03" rpy="0.000000000000e+00 -0.000000000000e+00 0.000000000000e+00"/><geometry><box size="8.000000000000e-03 2.400000000000e-02 9.600000000000e-03"/></geometry>
</visual>
    <collision><origin xyz="0.000000000000e+00 -8.000000000000e-03 4.800000000000e-03" rpy="0.000000000000e+00 -0.000000000000e+00 0.000000000000e+00"/><geometry><box size="8.000000000000e-03 2.400000000000e-02 9.600000000000e-03"/></geometry>
</collision>
    <inertial>
      <mass value="2.377730000000e-03"/>
      <origin xyz="-3.469450000000e-18 -8.000000000000e-03 4.800000000000e-03"/>
      <inertia ixx="1.323920000000e-07" ixy="0.000000000000e+00" ixz="0.000000000000e+00" iyy="3.094220000000e-08" iyz="0.000000000000e+00" izz="1.268120000000e-07"/>
    </inertial>
  </link>
  <joint name="block_1_3_213_34" type="fixed">
    <parent link="Root"/>
    <child link="block_1_3_213_34"/>
    <origin xyz="4.800000000000e-02 8.000000000000e-03 3.200000000000e-03" rpy="0.000000000000e+00 -0.000000000000e+00 0.000000000000e+00"/>
  </joint>
  <link name="block_1_3_213_35" >
    <visual><origin xyz="0.000000000000e+00 8.000000000000e-03 4.800000000000e-03" rpy="0.000000000000e+00 -0.000000000000e+00 0.000000000000e+00"/><geometry><box size="8.000000000000e-03 2.400000000000e-02 9.600000000000e-03"/></geometry>
</visual>
    <collision><origin xyz="0.000000000000e+00 8.000000000000e-03 4.800000000000e-03" rpy="0.000000000000e+00 -0.000000000000e+00 0.000000000000e+00"/><geometry><box size="8.000000000000e-03 2.400000000000e-02 9.600000000000e-03"/></geometry>
</collision>
    <inertial>
      <mass value="2.377730000000e-03"/>
      <origin xyz="-3.469450000000e-18 8.000000000000e-03 4.800000000000e-03"/>
      <inertia ixx="1.323920000000e-07" ixy="0.000000000000e+00" ixz="0.000000000000e+00" iyy="3.094220000000e-08" iyz="0.000000000000e+00" izz="1.268120000000e-07"/>
    </inertial>
  </link>
  <joint name="block_1_3_213_35" type="fixed">
    <parent link="block_1_3_213_34"/>
    <child link="block_1_3_213_35"/>
    <origin xyz="0.000000000000e+00 -1.600000000000e-02 9.600000000000e-03" rpy="0.000000000000e+00 -0.000000000000e+00 0.000000000000e+00"/>
  </joint>
  <link name="block_1_3_213_36" >
    <visual><origin xyz="0.000000000000e+00 8.000000000000e-03 4.800000000000e-03" rpy="0.000000000000e+00 -0.000000000000e+00 0.000000000000e+00"/><geometry><box size="8.000000000000e-03 2.400000000000e-02 9.600000000000e-03"/></geometry>
</visual>
    <collision><origin xyz="0.000000000000e+00 8.000000000000e-03 4.800000000000e-03" rpy="0.000000000000e+00 -0.000000000000e+00 0.000000000000e+00"/><geometry><box size="8.000000000000e-03 2.400000000000e-02 9.600000000000e-03"/></geometry>
</collision>
    <inertial>
      <mass value="2.377730000000e-03"/>
      <origin xyz="-3.469450000000e-18 8.000000000000e-03 4.800000000000e-03"/>
      <inertia ixx="1.323920000000e-07" ixy="0.000000000000e+00" ixz="0.000000000000e+00" iyy="3.094220000000e-08" iyz="0.000000000000e+00" izz="1.268120000000e-07"/>
    </inertial>
  </link>
  <joint name="block_1_3_213_36" type="fixed">
    <parent link="block_1_3_213_35"/>
    <child link="block_1_3_213_36"/>
    <origin xyz="0.000000000000e+00 0.000000000000e+00 9.600000000000e-03" rpy="0.000000000000e+00 -0.000000000000e+00 0.000000000000e+00"/>
  </joint>
  <link name="block_1_3_213_37" >
    <visual><origin xyz="0.000000000000e+00 8.000000000000e-03 4.800000000000e-03" rpy="0.000000000000e+00 -0.000000000000e+00 0.000000000000e+00"/><geometry><box size="8.000000000000e-03 2.400000000000e-02 9.600000000000e-03"/></geometry>
</visual>
    <collision><origin xyz="0.000000000000e+00 8.000000000000e-03 4.800000000000e-03" rpy="0.000000000000e+00 -0.000000000000e+00 0.000000000000e+00"/><geometry><box size="8.000000000000e-03 2.400000000000e-02 9.600000000000e-03"/></geometry>
</collision>
    <inertial>
      <mass value="2.377730000000e-03"/>
      <origin xyz="-3.469450000000e-18 8.000000000000e-03 4.800000000000e-03"/>
      <inertia ixx="1.323920000000e-07" ixy="0.000000000000e+00" ixz="0.000000000000e+00" iyy="3.094220000000e-08" iyz="0.000000000000e+00" izz="1.268120000000e-07"/>
    </inertial>
  </link>
  <joint name="block_1_3_213_37" type="fixed">
    <parent link="block_1_3_213_36"/>
    <child link="block_1_3_213_37"/>
    <origin xyz="0.000000000000e+00 0.000000000000e+00 9.600000000000e-03" rpy="0.000000000000e+00 -0.000000000000e+00 0.000000000000e+00"/>
  </joint>
  <link name="block_1_3_213_38" >
    <visual><origin xyz="0.000000000000e+00 8.000000000000e-03 4.800000000000e-03" rpy="0.000000000000e+00 -0.000000000000e+00 0.000000000000e+00"/><geometry><box size="8.000000000000e-03 2.400000000000e-02 9.600000000000e-03"/></geometry>
</visual>
    <collision><origin xyz="0.000000000000e+00 8.000000000000e-03 4.800000000000e-03" rpy="0.000000000000e+00 -0.000000000000e+00 0.000000000000e+00"/><geometry><box size="8.000000000000e-03 2.400000000000e-02 9.600000000000e-03"/></geometry>
</collision>
    <inertial>
      <mass value="2.377730000000e-03"/>
      <origin xyz="-3.469450000000e-18 8.000000000000e-03 4.800000000000e-03"/>
      <inertia ixx="1.323920000000e-07" ixy="0.000000000000e+00" ixz="0.000000000000e+00" iyy="3.094220000000e-08" iyz="0.000000000000e+00" izz="1.268120000000e-07"/>
    </inertial>
  </link>
  <joint name="block_1_3_213_38" type="fixed">
    <parent link="block_1_3_213_37"/>
    <child link="block_1_3_213_38"/>
    <origin xyz="0.000000000000e+00 0.000000000000e+00 9.600000000000e-03" rpy="0.000000000000e+00 -0.000000000000e+00 0.000000000000e+00"/>
  </joint>
  <link name="FR12_S102_P_213_1" >
    <visual><geometry><mesh filename="file:///tmp/AssembleRobot_FR12_S102_P_213_1_vis.dae"/></geometry></visual>
    <collision><geometry><mesh filename="file:///tmp/AssembleRobot_FR12_S102_P_213_1_col.stl"/></geometry></collision>
    <inertial>
      <mass value="9.852000000000e-03"/>
      <origin xyz="-1.200000000000e-02 -8.000000000000e-03 -4.616000000000e-03"/>
      <inertia ixx="6.999420000000e-07" ixy="0.000000000000e+00" ixz="6.952000000000e-19" iyy="1.667410000000e-06" iyz="0.000000000000e+00" izz="2.086850000000e-06"/>
    </inertial>
  </link>
  <joint name="FR12_S102_P_213_1" type="fixed">
    <parent link="Root"/>
    <child link="FR12_S102_P_213_1"/>
    <origin xyz="4.800000000000e-02 8.000000000000e-03 0.000000000000e+00" rpy="0.000000000000e+00 -0.000000000000e+00 0.000000000000e+00"/>
  </joint>
  <link name="XL-430_213_6" >
    <visual><geometry><mesh filename="file:///tmp/AssembleRobot_XL-430_213_6_vis.dae"/></geometry></visual>
    <collision><geometry><mesh filename="file:///tmp/AssembleRobot_XL-430_213_6_col.stl"/></geometry></collision>
    <inertial>
      <mass value="5.700000000000e-02"/>
      <origin xyz="1.661280000000e-02 -1.141970000000e-02 -1.547430000000e-02"/>
      <inertia ixx="8.252850000000e-06" ixy="1.751460000000e-07" ixz="-8.492440000000e-07" iyy="1.549380000000e-05" iyz="4.811160000000e-08" izz="1.374130000000e-05"/>
    </inertial>
  </link>
  <joint name="XL-430_213_6" type="fixed">
    <parent link="FR12_S102_P_213_1"/>
    <child link="XL-430_213_6"/>
    <origin xyz="5.000000000000e-03 3.000000000000e-03 -1.320000000000e-02" rpy="-0.000000000000e+00 1.570796326795e+00 0.000000000000e+00"/>
  </joint>
  <link name="LINK_6" >
    <visual><geometry><mesh filename="file:///tmp/AssembleRobot_LINK_6_vis.dae"/></geometry></visual>
    <collision><geometry><mesh filename="file:///tmp/AssembleRobot_LINK_6_col.stl"/></geometry></collision>
    <inertial>
      <mass value="5.733000000000e-03"/>
      <origin xyz="-1.800000000000e-05 1.700000000000e-05 1.291500000000e-02"/>
      <inertia ixx="5.924300000000e-07" ixy="4.360000000000e-10" ixz="6.570000000000e-10" iyy="5.924600000000e-07" iyz="-6.350000000000e-10" izz="1.839640000000e-07"/>
    </inertial>
  </link>
  <joint name="LINK_6" type="revolute">
    <parent link="XL-430_213_6"/>
    <child link="LINK_6"/>
    <origin xyz="3.200000000000e-02 -1.100000000000e-02 2.000000000000e-03" rpy="-3.140180000000e-16 -2.465190328816e-32 1.570796326795e+00"/>
    <axis xyz="0.000000000000e+00 0.000000000000e+00 1.000000000000e+00"/>
    <limit lower="-3.141592653590e+10" upper="3.141592653590e+10" velocity="1.797693134862e+308" effort="1.797693134862e+308"/>
  </joint>
  <xacro:gazebo_transmission joint_name="LINK_6"/>
  <link name="omni-wheel_213_14" >
    <visual><geometry><mesh filename="file:///tmp/AssembleRobot_omni-wheel_213_14_vis.dae"/></geometry></visual>
    <collision><geometry><mesh filename="file:///tmp/AssembleRobot_omni-wheel_213_14_col.stl"/></geometry></collision>
    <inertial>
      <mass value="5.479700000000e-02"/>
      <origin xyz="2.725000000000e-12 -6.938890000000e-18 -1.255000000000e-02"/>
      <inertia ixx="1.126680000000e-05" ixy="0.000000000000e+00" ixz="-1.582000000000e-18" iyy="1.126680000000e-05" iyz="0.000000000000e+00" izz="1.680300000000e-05"/>
    </inertial>
  </link>
  <joint name="omni-wheel_213_14" type="fixed">
    <parent link="LINK_6"/>
    <child link="omni-wheel_213_14"/>
    <origin xyz="2.367534269115e-30 -8.491693428602e-19 3.000000000000e-02" rpy="0.000000000000e+00 -3.007574964758e-32 0.000000000000e+00"/>
  </joint>
  <link name="FR12_S102_P_213_3" >
    <visual><geometry><mesh filename="file:///tmp/AssembleRobot_FR12_S102_P_213_3_vis.dae"/></geometry></visual>
    <collision><geometry><mesh filename="file:///tmp/AssembleRobot_FR12_S102_P_213_3_col.stl"/></geometry></collision>
    <inertial>
      <mass value="9.852000000000e-03"/>
      <origin xyz="1.200000000000e-02 8.000000000000e-03 -4.616000000000e-03"/>
      <inertia ixx="6.999420000000e-07" ixy="0.000000000000e+00" ixz="6.952000000000e-19" iyy="1.667410000000e-06" iyz="0.000000000000e+00" izz="2.086850000000e-06"/>
    </inertial>
  </link>
  <joint name="FR12_S102_P_213_3" type="fixed">
    <parent link="Root"/>
    <child link="FR12_S102_P_213_3"/>
    <origin xyz="-4.800000000000e-02 -8.000000000000e-03 0.000000000000e+00" rpy="0.000000000000e+00 -0.000000000000e+00 0.000000000000e+00"/>
  </joint>
  <link name="XL-430_213_8" >
    <visual><geometry><mesh filename="file:///tmp/AssembleRobot_XL-430_213_8_vis.dae"/></geometry></visual>
    <collision><geometry><mesh filename="file:///tmp/AssembleRobot_XL-430_213_8_col.stl"/></geometry></collision>
    <inertial>
      <mass value="5.700000000000e-02"/>
      <origin xyz="1.661280000000e-02 -1.141970000000e-02 -1.547430000000e-02"/>
      <inertia ixx="8.252850000000e-06" ixy="1.751460000000e-07" ixz="-8.492440000000e-07" iyy="1.549380000000e-05" iyz="4.811160000000e-08" izz="1.374130000000e-05"/>
    </inertial>
  </link>
  <joint name="XL-430_213_8" type="fixed">
    <parent link="FR12_S102_P_213_3"/>
    <child link="XL-430_213_8"/>
    <origin xyz="-5.000000000000e-03 -3.000000000000e-03 -1.320000000000e-02" rpy="3.141592653585e+00 1.570776527811e+00 -4.373696624297e-12"/>
  </joint>
  <link name="LINK_7" >
    <visual><geometry><mesh filename="file:///tmp/AssembleRobot_LINK_7_vis.dae"/></geometry></visual>
    <collision><geometry><mesh filename="file:///tmp/AssembleRobot_LINK_7_col.stl"/></geometry></collision>
    <inertial>
      <mass value="5.733000000000e-03"/>
      <origin xyz="-1.800000000000e-05 1.700000000000e-05 1.291500000000e-02"/>
      <inertia ixx="5.924300000000e-07" ixy="4.360000000000e-10" ixz="6.570000000000e-10" iyy="5.924600000000e-07" iyz="-6.350000000000e-10" izz="1.839640000000e-07"/>
    </inertial>
  </link>
  <joint name="LINK_7" type="revolute">
    <parent link="XL-430_213_8"/>
    <child link="LINK_7"/>
    <origin xyz="3.200000000000e-02 -1.100000000000e-02 2.000000000000e-03" rpy="3.981020970777e-16 7.850510000000e-17 -1.570796326795e+00"/>
    <axis xyz="0.000000000000e+00 0.000000000000e+00 1.000000000000e+00"/>
    <limit lower="-3.141592653590e+10" upper="3.141592653590e+10" velocity="1.797693134862e+308" effort="1.797693134862e+308"/>
  </joint>
  <xacro:gazebo_transmission joint_name="LINK_7"/>
  <link name="omni-wheel_213_16" >
    <visual><geometry><mesh filename="file:///tmp/AssembleRobot_omni-wheel_213_16_vis.dae"/></geometry></visual>
    <collision><geometry><mesh filename="file:///tmp/AssembleRobot_omni-wheel_213_16_col.stl"/></geometry></collision>
    <inertial>
      <mass value="5.479700000000e-02"/>
      <origin xyz="2.724990000000e-12 -3.469450000000e-18 -1.255000000000e-02"/>
      <inertia ixx="1.126680000000e-05" ixy="0.000000000000e+00" ixz="-1.582000000000e-18" iyy="1.126680000000e-05" iyz="0.000000000000e+00" izz="1.680300000000e-05"/>
    </inertial>
  </link>
  <joint name="omni-wheel_213_16" type="fixed">
    <parent link="LINK_7"/>
    <child link="omni-wheel_213_16"/>
    <origin xyz="6.661470000000e-18 1.971479772646e-17 3.000000000000e-02" rpy="5.551115123126e-16 -5.392603844284e-32 -4.930380657631e-32"/>
  </joint>
  <link name="block_1_3_213_29" >
    <visual><origin xyz="0.000000000000e+00 -8.000000000000e-03 4.800000000000e-03" rpy="0.000000000000e+00 -0.000000000000e+00 0.000000000000e+00"/><geometry><box size="8.000000000000e-03 2.400000000000e-02 9.600000000000e-03"/></geometry>
</visual>
    <collision><origin xyz="0.000000000000e+00 -8.000000000000e-03 4.800000000000e-03" rpy="0.000000000000e+00 -0.000000000000e+00 0.000000000000e+00"/><geometry><box size="8.000000000000e-03 2.400000000000e-02 9.600000000000e-03"/></geometry>
</collision>
    <inertial>
      <mass value="2.377730000000e-03"/>
      <origin xyz="-3.469450000000e-18 -8.000000000000e-03 4.800000000000e-03"/>
      <inertia ixx="1.323920000000e-07" ixy="0.000000000000e+00" ixz="0.000000000000e+00" iyy="3.094220000000e-08" iyz="0.000000000000e+00" izz="1.268120000000e-07"/>
    </inertial>
  </link>
  <joint name="block_1_3_213_29" type="fixed">
    <parent link="Root"/>
    <child link="block_1_3_213_29"/>
    <origin xyz="-4.800000000000e-02 8.000000000000e-03 3.200000000000e-03" rpy="0.000000000000e+00 -0.000000000000e+00 0.000000000000e+00"/>
  </joint>
  <link name="block_1_3_213_30" >
    <visual><origin xyz="0.000000000000e+00 8.000000000000e-03 4.800000000000e-03" rpy="0.000000000000e+00 -0.000000000000e+00 0.000000000000e+00"/><geometry><box size="8.000000000000e-03 2.400000000000e-02 9.600000000000e-03"/></geometry>
</visual>
    <collision><origin xyz="0.000000000000e+00 8.000000000000e-03 4.800000000000e-03" rpy="0.000000000000e+00 -0.000000000000e+00 0.000000000000e+00"/><geometry><box size="8.000000000000e-03 2.400000000000e-02 9.600000000000e-03"/></geometry>
</collision>
    <inertial>
      <mass value="2.377730000000e-03"/>
      <origin xyz="-3.469450000000e-18 8.000000000000e-03 4.800000000000e-03"/>
      <inertia ixx="1.323920000000e-07" ixy="0.000000000000e+00" ixz="0.000000000000e+00" iyy="3.094220000000e-08" iyz="0.000000000000e+00" izz="1.268120000000e-07"/>
    </inertial>
  </link>
  <joint name="block_1_3_213_30" type="fixed">
    <parent link="block_1_3_213_29"/>
    <child link="block_1_3_213_30"/>
    <origin xyz="0.000000000000e+00 -1.600000000000e-02 9.600000000000e-03" rpy="0.000000000000e+00 -0.000000000000e+00 0.000000000000e+00"/>
  </joint>
  <link name="block_1_3_213_31" >
    <visual><origin xyz="0.000000000000e+00 8.000000000000e-03 4.800000000000e-03" rpy="0.000000000000e+00 -0.000000000000e+00 0.000000000000e+00"/><geometry><box size="8.000000000000e-03 2.400000000000e-02 9.600000000000e-03"/></geometry>
</visual>
    <collision><origin xyz="0.000000000000e+00 8.000000000000e-03 4.800000000000e-03" rpy="0.000000000000e+00 -0.000000000000e+00 0.000000000000e+00"/><geometry><box size="8.000000000000e-03 2.400000000000e-02 9.600000000000e-03"/></geometry>
</collision>
    <inertial>
      <mass value="2.377730000000e-03"/>
      <origin xyz="-3.469450000000e-18 8.000000000000e-03 4.800000000000e-03"/>
      <inertia ixx="1.323920000000e-07" ixy="0.000000000000e+00" ixz="0.000000000000e+00" iyy="3.094220000000e-08" iyz="0.000000000000e+00" izz="1.268120000000e-07"/>
    </inertial>
  </link>
  <joint name="block_1_3_213_31" type="fixed">
    <parent link="block_1_3_213_30"/>
    <child link="block_1_3_213_31"/>
    <origin xyz="0.000000000000e+00 0.000000000000e+00 9.600000000000e-03" rpy="0.000000000000e+00 -0.000000000000e+00 0.000000000000e+00"/>
  </joint>
  <link name="block_1_3_213_32" >
    <visual><origin xyz="0.000000000000e+00 8.000000000000e-03 4.800000000000e-03" rpy="0.000000000000e+00 -0.000000000000e+00 0.000000000000e+00"/><geometry><box size="8.000000000000e-03 2.400000000000e-02 9.600000000000e-03"/></geometry>
</visual>
    <collision><origin xyz="0.000000000000e+00 8.000000000000e-03 4.800000000000e-03" rpy="0.000000000000e+00 -0.000000000000e+00 0.000000000000e+00"/><geometry><box size="8.000000000000e-03 2.400000000000e-02 9.600000000000e-03"/></geometry>
</collision>
    <inertial>
      <mass value="2.377730000000e-03"/>
      <origin xyz="-3.469450000000e-18 8.000000000000e-03 4.800000000000e-03"/>
      <inertia ixx="1.323920000000e-07" ixy="0.000000000000e+00" ixz="0.000000000000e+00" iyy="3.094220000000e-08" iyz="0.000000000000e+00" izz="1.268120000000e-07"/>
    </inertial>
  </link>
  <joint name="block_1_3_213_32" type="fixed">
    <parent link="block_1_3_213_31"/>
    <child link="block_1_3_213_32"/>
    <origin xyz="0.000000000000e+00 0.000000000000e+00 9.600000000000e-03" rpy="0.000000000000e+00 -0.000000000000e+00 0.000000000000e+00"/>
  </joint>
  <link name="block_1_3_213_33" >
    <visual><origin xyz="0.000000000000e+00 8.000000000000e-03 4.800000000000e-03" rpy="0.000000000000e+00 -0.000000000000e+00 0.000000000000e+00"/><geometry><box size="8.000000000000e-03 2.400000000000e-02 9.600000000000e-03"/></geometry>
</visual>
    <collision><origin xyz="0.000000000000e+00 8.000000000000e-03 4.800000000000e-03" rpy="0.000000000000e+00 -0.000000000000e+00 0.000000000000e+00"/><geometry><box size="8.000000000000e-03 2.400000000000e-02 9.600000000000e-03"/></geometry>
</collision>
    <inertial>
      <mass value="2.377730000000e-03"/>
      <origin xyz="-3.469450000000e-18 8.000000000000e-03 4.800000000000e-03"/>
      <inertia ixx="1.323920000000e-07" ixy="0.000000000000e+00" ixz="0.000000000000e+00" iyy="3.094220000000e-08" iyz="0.000000000000e+00" izz="1.268120000000e-07"/>
    </inertial>
  </link>
  <joint name="block_1_3_213_33" type="fixed">
    <parent link="block_1_3_213_32"/>
    <child link="block_1_3_213_33"/>
    <origin xyz="0.000000000000e+00 0.000000000000e+00 9.600000000000e-03" rpy="0.000000000000e+00 -0.000000000000e+00 0.000000000000e+00"/>
  </joint>
</robot>
